<?xml version="1.0" encoding="UTF-8"?>
<robot name="ezgripper_quad" xmlns:xacro="http://ros.org/wiki/xacro">


	<xacro:macro name="ezgripper_quad" params="prefix parent_link *origin">

		<!-- links -->

		<link name="${prefix}_ezgripper_palm_link">
			<visual>
				<origin xyz="0 0 0" rpy="0 0 0"/>
				<geometry>
					<mesh filename="package://ezgripper_description/meshes/quad/SAKE_Palm_Quad.stl"/>
				</geometry>
				<material name="blue"/>
			</visual>
			<collision>
				<origin xyz="0 0 0" rpy="0 0 0"/>
				<geometry>
					<mesh filename="package://ezgripper_description/meshes/quad/SAKE_Palm_Quad.stl"/>
				</geometry>
			</collision>
			<inertial>
				<mass value=".3"/>
				<inertia ixx="0.01" ixy="0.0" ixz="0.0" iyy="0.01" iyz="0.0" izz="0.01"/>
			</inertial>
		</link>

		<gazebo reference="${prefix}_ezgripper_palm_link">
			<material>Gazebo/Blue</material>
		</gazebo>

		<joint name="${prefix}_ezgripper_connect" type="fixed">
				<xacro:insert_block name="origin" />
				<parent link="${parent_link}"/>
				<child link="${prefix}_ezgripper_palm_link"/>
				<axis xyz="0 0 0"/>
				<limit effort="0" lower="-1.57075" upper="0.25" velocity="3.67"/>
		</joint>

		<xacro:ezgripper_finger prefix="${prefix}" postfix="1" reflect="1"/>
		<xacro:ezgripper_finger prefix="${prefix}" postfix="2" reflect="1"/>
		<xacro:ezgripper_finger prefix="${prefix}" postfix="3" reflect="1"/>
		<xacro:ezgripper_finger prefix="${prefix}" postfix="4" reflect="1"/>

		<!-- Mimic Test has to be set false for the first joint -->
		<xacro:ezgripper_knuckle prefix="${prefix}" postfix="1" reflectY="1" reflectZ="1" reflectR="1" mimic_test="false"/>
		<xacro:ezgripper_knuckle prefix="${prefix}" postfix="2" reflectY="-1" reflectZ="1" reflectR="-1" mimic_test="true"/>
		<xacro:ezgripper_knuckle prefix="${prefix}" postfix="3" reflectY="1" reflectZ="-1" reflectR="1" mimic_test="true"/>
		<xacro:ezgripper_knuckle prefix="${prefix}" postfix="4" reflectY="-1" reflectZ="-1" reflectR="-1" mimic_test="true"/>

		<!-- Transmission needs to be removed when mimicked -->
		<xacro:ezgripper_knuckle_trans prefix="${prefix}" postfix="1"/>
		<!-- <xacro:ezgripper_knuckle_trans prefix="${prefix}" postfix="2"/>
		<xacro:ezgripper_knuckle_trans prefix="${prefix}" postfix="3"/>
		<xacro:ezgripper_knuckle_trans prefix="${prefix}" postfix="4"/> -->

		<xacro:gazebo_knuckle_jsp prefix="${prefix}" />


	</xacro:macro>


	<xacro:macro name="ezgripper_finger" params="prefix postfix reflect">

		<link name="${prefix}_ezgripper_finger_${postfix}">
			<visual>
				<origin xyz="0 0 0" rpy="0 0 0"/>
				<geometry>
					<mesh filename="package://ezgripper_description/meshes/quad/SAKE_Finger.stl"/>
				</geometry>
				<material name="grey"/>
			</visual>
			<collision>
				<origin xyz="0 0 0" rpy="0 0 0"/>
				<geometry>
					<mesh filename="package://ezgripper_description/meshes/quad/SAKE_Finger.stl"/>
				</geometry>
			</collision>
			<inertial>
				<mass value=".025"/>
				<inertia ixx="0.01" ixy="0.0" ixz="0.0" iyy=".01" iyz="0.0" izz="0.01"/>
			</inertial>
		</link>

		<gazebo reference="${prefix}_ezgripper_finger_${postfix}">
			<material>Gazebo/Grey</material>
		</gazebo>

	</xacro:macro>


	<!-- joints -->
	<xacro:macro name="ezgripper_knuckle" params="prefix postfix reflectY reflectZ reflectR mimic_test">
		<joint name="${prefix}_ezgripper_knuckle_${postfix}" type="revolute">
			<parent link="${prefix}_ezgripper_palm_link"/>
			<child link="${prefix}_ezgripper_finger_${postfix}"/>
			<origin xyz="0.1056 ${reflectY*0.03} ${reflectZ*0.03}" rpy="${1.5708 * reflectR} 0 3.14159"/>
			<axis xyz="0 1 0"/>
			<limit lower="-.27" upper="1.57075" effort="1" velocity="3.67"/>
			<xacro:if value="${mimic_test}">
					<mimic joint="${prefix}_ezgripper_knuckle_1"/>
			</xacro:if>
		</joint>
	</xacro:macro>

			<!-- transmissions for Gazebo -->

	<xacro:macro name="ezgripper_knuckle_trans" params="prefix postfix">
		<transmission name="${prefix}_ezgripper_trans_${postfix}">
				<type>transmission_interface/SimpleTransmission</type>
				<joint name="${prefix}_ezgripper_knuckle_${postfix}">
					<hardwareInterface>hardware_interface/PositionJointInterface</hardwareInterface>
				</joint>
				<actuator name="${prefix}_ezgripper_motor${postfix}">
					<mechanicalReduction>1</mechanicalReduction>
					<hardwareInterface>hardware_interface/PositionJointInterface</hardwareInterface>
				</actuator>
		</transmission>
	</xacro:macro>

	<xacro:macro name="gazebo_knuckle_jsp" params="prefix">
			<gazebo>
				<plugin name="joint_state_publisher" filename="libgazebo_ros_joint_state_publisher.so">
					<jointName>${prefix}_ezgripper_knuckle_1</jointName>
				</plugin>
			</gazebo>
	</xacro:macro>

	<gazebo>

		<plugin name="gazebo_ros_control" filename="libgazebo_ros_control.so">
			<robotNamespace>ezgripper_quad</robotNamespace>
			<legacyModeNS>true</legacyModeNS>
		</plugin>

		<!-- Fix mimicking bug -->
		<plugin filename="libroboticsgroup_upatras_gazebo_mimic_joint_plugin.so" name="mimicker">
			<joint>left_ezgripper_knuckle_1</joint>
			<mimicJoint>left_ezgripper_knuckle_2</mimicJoint>
		</plugin>

		<plugin filename="libroboticsgroup_upatras_gazebo_mimic_joint_plugin.so" name="mimicker">
			<joint>left_ezgripper_knuckle_1</joint>
			<mimicJoint>left_ezgripper_knuckle_3</mimicJoint>
		</plugin>

		<plugin filename="libroboticsgroup_upatras_gazebo_mimic_joint_plugin.so" name="mimicker">
			<joint>left_ezgripper_knuckle_1</joint>
			<mimicJoint>left_ezgripper_knuckle_4</mimicJoint>
		</plugin>

	</gazebo>

</robot>
